# 错误处理机制

JavaScript 解析或运行时，一旦发生错误，引擎就会抛出一个错误对象。JavaScript 原生提供Error构造函数，所有抛出的错误都是这个构造函数的实例。
抛出Error实例对象以后，整个程序就中断在发生错误的地方，不再往下执行。
JavaScript 语言标准只提到，Error实例对象必须有message属性，表示出错时的提示信息，没有提到其他属性。

message：错误提示信息
name：错误名称（非标准属性）
stack：错误的堆栈（非标准属性）

## 错误类型

Error实例对象是最一般的错误类型，在它的基础上，JavaScript 还定义了其他6种错误对象。也就是说，存在Error的6个派生对象。

* SyntaxError对象是解析代码时发生的语法错误。
* ReferenceError对象是引用一个不存在的变量时发生的错误。
* RangeError对象是一个值超出有效范围时发生的错误。主要有几种情况，一是数组长度为负数，二是Number对象的方法参数超出范围，以及函数堆栈超过最大值。
* TypeError对象是变量或参数不是预期类型时发生的错误。比如，对字符串、布尔值、数值等原始类型的值使用new命令，就会抛出这种错误，因为new命令的参数应该是一个构造函数。
* URIError对象是 URI 相关函数的参数不正确时抛出的错误，主要涉及encodeURI()、decodeURI()、encodeURIComponent()、decodeURIComponent()、escape()和unescape()这六个函数。

## throw

throw语句的作用是手动中断程序执行，抛出一个错误。
实际上，throw可以抛出任何类型的值。也就是说，它的参数可以是任何值。
对于 JavaScript 引擎来说，遇到throw语句，程序就中止了。

## try...catch
一旦发生错误，程序就中止执行了。JavaScript 提供了try...catch结构，允许对错误进行处理，选择是否往下执行。
为了捕捉不同类型的错误，catch代码块之中可以加入判断语句。
这里, 其他的类型语言里面, 其实是根据 catch 里面的类型进入不同的 catch, 但是因为 JS 里面函数参数没有类型, 所以只能写在里面做判断了.
因为 catch 里面没有类型判断, 所以异常到这里都算被处理了. 这个时候, 如果本地代码在判断类型之后不知道怎么处理未知类型的异常, 应该重新抛出原来的异常 

``` JS
try {
  throw new Error('出错了!');
} catch (e) {
  console.log(e.name + ": " + e.message);
  console.log(e.stack);
}

try {
  foo.bar();
} catch (e) {
  if (e instanceof EvalError) {
    console.log(e.name + ": " + e.message);
  } else if (e instanceof RangeError) {
    console.log(e.name + ": " + e.message);
  } else {
      throw e
  } finally {
    console.log('完成清理工作');
  }
  // ...
}

```
try...catch结构允许在最后添加一个finally代码块，表示不管是否出现错误，都必需在最后运行的语句。
return语句的执行是排在finally代码之前，只是等finally代码执行完毕后才返回。
